Internal Server Error: /editor
Traceback (most recent call last):
  File "/home/runner/workspace/.pythonlibs/lib/python3.12/site-packages/django/core/handlers/exception.py", line 55, in inner
    response = get_response(request)
               ^^^^^^^^^^^^^^^^^^^^^
  File "/home/runner/workspace/.pythonlibs/lib/python3.12/site-packages/django/core/handlers/base.py", line 197, in _get_response
    response = wrapped_callback(request, *callback_args, **callback_kwargs)
               ^^^^^^^^^^^^^^^^^^^^^^^^^^^^^^^^^^^^^^^^^^^^^^^^^^^^^^^^^^^^
  File "/home/runner/workspace/quizzy_app/views.py", line 876, in editor
    correct_2 = process_with_ai(json.loads(Auto_Correct_2))
                ^^^^^^^^^^^^^^^^^^^^^^^^^^^^^^^^^^^^^^^^^^^
  File "/home/runner/workspace/quizzy_app/corrector_2.py", line 26, in process_with_ai
    response = chat_session.send_message(f"""
              ^^^^^^^^^^^^^^^^^^^^^^^^^^^^^^
  File "/home/runner/workspace/.pythonlibs/lib/python3.12/site-packages/google/generativeai/generative_models.py", line 578, in send_message
    response = self.model.generate_content(
               ^^^^^^^^^^^^^^^^^^^^^^^^^^^^
  File "/home/runner/workspace/.pythonlibs/lib/python3.12/site-packages/google/generativeai/generative_models.py", line 331, in generate_content
    response = self._client.generate_content(
               ^^^^^^^^^^^^^^^^^^^^^^^^^^^^^^
  File "/home/runner/workspace/.pythonlibs/lib/python3.12/site-packages/google/ai/generativelanguage_v1beta/services/generative_service/client.py", line 824, in generate_content
    self._validate_universe_domain()
  File "/home/runner/workspace/.pythonlibs/lib/python3.12/site-packages/google/ai/generativelanguage_v1beta/services/generative_service/client.py", line 519, in _validate_universe_domain
    or GenerativeServiceClient._compare_universes(
       ^^^^^^^^^^^^^^^^^^^^^^^^^^^^^^^^^^^^^^^^^^^
  File "/home/runner/workspace/.pythonlibs/lib/python3.12/site-packages/google/ai/generativelanguage_v1beta/services/generative_service/client.py", line 496, in _compare_universes
    credentials_universe = getattr(credentials, "universe_domain", default_universe)
                           ^^^^^^^^^^^^^^^^^^^^^^^^^^^^^^^^^^^^^^^^^^^^^^^^^^^^^^^^^
  File "/home/runner/workspace/.pythonlibs/lib/python3.12/site-packages/google/auth/compute_engine/credentials.py", line 154, in universe_domain
    self._universe_domain = _metadata.get_universe_domain(
                            ^^^^^^^^^^^^^^^^^^^^^^^^^^^^^^
  File "/home/runner/workspace/.pythonlibs/lib/python3.12/site-packages/google/auth/compute_engine/_metadata.py", line 308, in get_universe_domain
    universe_domain = get(
                      ^^^^
  File "/home/runner/workspace/.pythonlibs/lib/python3.12/site-packages/google/auth/compute_engine/_metadata.py", line 239, in get
    raise exceptions.TransportError(
google.auth.exceptions.TransportError: Failed to retrieve http://metadata.google.internal/computeMetadata/v1/universe/universe-domain from the Google Compute Engine metadata service. Compute Engine Metadata server unavailable due to HTTPConnectionPool(host='metadata.google.internal', port=80): Max retries exceeded with url: /computeMetadata/v1/universe/universe-domain (Caused by NameResolutionError("<urllib3.connection.HTTPConnection object at 0x7fe1d12f6fc0>: Failed to resolve 'metadata.google.internal' ([Errno -2] Name or service not known)"))
[01/Jun/2025 20:31:16] "POST /editor?session=b%27gAAAAABoPLaQw4BzTkobui7d0ZhW_Id0GyVG6hb9SccsdR4hCoRxI92IwZO5VoaYPL1jzYXcVihCaKTLxnA2azJ6atfnGYMmPQ==%27 HTTP/1.1" 500 202619